<?xml version="1.0" ?>
<!-- =================================================================================== -->
<!-- |    This document was autogenerated by xacro from phantomx/phantomx.xacro        | -->
<!-- |    EDITING THIS FILE BY HAND IS NOT RECOMMENDED                                 | -->
<!-- =================================================================================== -->
<robot name="phantomx" xmlns:xacro="http://www.ros.org/wiki/xacro">
  <material name="Blue">
    <color rgba="0.33 0.25 1.0 1.0"/>
  </material>
  <material name="DarkBlue">
    <color rgba="0.03 0.16 0.8 1.0"/>
  </material>
  <material name="Green">
    <color rgba="0.0 0.8 0.0 1.0"/>
  </material>
  <material name="Grey">
    <color rgba="0.7 0.7 0.7 1.0"/>
  </material>
  <material name="DarkGreen">
    <color rgba="0.4 0.6 0.24 1.0"/>
  </material>
  <material name="Red">
    <color rgba="0.48 0.03 0.03 1.0"/>
  </material>
  <material name="White">
    <color rgba="1.0 1.0 1.0 1.0"/>
  </material>
  <material name="Yellow">
    <color rgba="1.0 0.8 0.0 1.0"/>
  </material>
  <!-- Build the body frame -->
  <link name="base_link"/>
  <joint name="j_phantomx_attachment" type="fixed">
    <parent link="base_link"/>
    <child link="MP_BODY"/>
    <origin rpy="0 0 0" xyz="0 0 0"/>
  </joint>
  <link name="MP_BODY">
    <inertial>
      <origin xyz="0 0 0"/>
      <mass value="0.97559947"/>
      <inertia ixx="3.1081800" ixy="-0.25460189" ixz="2.0318174" iyy="6.3787776" iyz="0.16417863" izz="5.3316425"/>
    </inertial>
    <visual>
      <!--origin xyz="-0.0235 0 -0.03525" rpy="0 0 0" /-->
      <origin rpy="0 0 0" xyz="0 0 0"/>
      <geometry>
        <!--box size="0.102 0.109 0.106" /-->
        <mesh filename="meshes/body.STL" scale="1 1 1"/>
      </geometry>
      <material name="Red"/>
    </visual>
    <collision>
      <origin rpy="0 0 0" xyz="0 0 0"/>
      <geometry>
        <mesh filename="meshes/body_coll.STL" scale="1 1 1"/>
      </geometry>
    </collision>
  </link>
  <link name="c1_rf">
    <inertial>
      <origin rpy="0 0 0" xyz="0 -0.02633 0"/>
      <mass value="0.024357719"/>
      <inertia ixx="0.0051411124" ixy="-0.00057530255" ixz="-0.000024729049" iyy="0.0081915737" iyz="-0.000019223094" izz="0.0011379812"/>
    </inertial>
    <visual>
      <origin rpy="0 0 0" xyz="0 -0.0252 0"/>
      <geometry>
        <!--box size="0.045 0.022 0.0325" /-->
        <mesh filename="meshes/connect.STL" scale="1 1 1"/>
      </geometry>
      <material name="Yellow"/>
    </visual>
    <collision>
      <origin rpy="0 0 0" xyz="0 -0.02633 0"/>
      <geometry>
        <mesh filename="meshes/connect_coll.STL" scale="1 1 1"/>
      </geometry>
    </collision>
  </link>
  <link name="c2_rf">
    <inertial>
      <origin rpy="0 0 0" xyz="0 -0.02633 0"/>
      <mass value="0.024357719"/>
      <inertia ixx="0.0051411124" ixy="-0.00057530255" ixz="-0.000024729049" iyy="0.0081915737" iyz="-0.000019223094" izz="0.0011379812"/>
    </inertial>
    <visual>
      <origin rpy="0 0 0" xyz="0 -0.0252 0"/>
      <geometry>
        <!--box size="0.045 0.022 0.0325" /-->
        <mesh filename="meshes/connect.STL" scale="1 1 1"/>
      </geometry>
      <material name="Yellow"/>
    </visual>
    <collision>
      <origin rpy="0 0 0" xyz="0 -0.02633 0"/>
      <geometry>
        <mesh filename="meshes/connect_coll.STL" scale="1 1 1"/>
      </geometry>
    </collision>
  </link>
  <link name="thigh_rf">
    <inertial>
      <origin rpy="0 0 0" xyz="0 0 0"/>
      <mass value="0.024357719"/>
      <inertia ixx="0.0051411124" ixy="-0.00057530255" ixz="-0.000024729049" iyy="0.0081915737" iyz="-0.000019223094" izz="0.0011379812"/>
    </inertial>
    <visual>
      <origin rpy="0 0 0" xyz="0 0 0"/>
      <geometry>
        <!--box size="0.045 0.022 0.0325" /-->
        <mesh filename="meshes/thigh_l.STL" scale="1 1 1"/>
      </geometry>
      <material name="DarkGreen"/>
    </visual>
    <collision>
      <origin rpy="0 0 0" xyz="0 0 0"/>
      <geometry>
        <mesh filename="meshes/thigh_l_coll.STL" scale="1 1 1"/>
      </geometry>
    </collision>
  </link>
  <link name="tibia_rf">
    <inertial>
      <origin rpy="0 0 0" xyz="0 0 0"/>
      <mass value="0.024357719"/>
      <inertia ixx="0.0051411124" ixy="-0.00057530255" ixz="-0.000024729049" iyy="0.0081915737" iyz="-0.000019223094" izz="0.0011379812"/>
    </inertial>
    <visual>
      <origin rpy="0 0 0" xyz="0 0 0"/>
      <geometry>
        <!--box size="0.045 0.022 0.0325" /-->
        <mesh filename="meshes/tibia_l.STL" scale="1 1 1"/>
      </geometry>
      <material name="Blue"/>
    </visual>
    <collision>
      <origin rpy="0 0 0" xyz="0 0 0"/>
      <geometry>
        <mesh filename="meshes/tibia_l_coll.STL" scale="1 1 1"/>
      </geometry>
    </collision>
  </link>
  <joint name="j_c1_rf" type="revolute">
    <parent link="MP_BODY"/>
    <child link="c1_rf"/>
    <origin rpy="0 4.7123 0.7853981633974483" xyz="0.1248 -0.06164  0.001116"/>
    <axis xyz="1 0 0"/>
    <limit effort="2.8" lower="-2.6179939" upper="2.6179939" velocity="5.6548668"/>
  </joint>
  <joint name="j_c2_rf" type="fixed">
    <parent link="c1_rf"/>
    <child link="c2_rf"/>
    <origin rpy="0 1.5704 3.14159" xyz="0 -0.054 0"/>
  </joint>
  <joint name="j_thigh_rf" type="revolute">
    <parent link="c2_rf"/>
    <child link="thigh_rf"/>
    <origin rpy=" 0 3.14159 3.14159" xyz="0 0 0"/>
    <axis xyz="1 0 0"/>
    <limit effort="2.8" lower="-2.6179939" upper="2.6179939" velocity="5.6548668"/>
  </joint>
  <joint name="j_tibia_rf" type="revolute">
    <parent link="thigh_rf"/>
    <child link="tibia_rf"/>
    <origin rpy="-1.5707 0 3.14159" xyz="0 -0.0645 -0.0145"/>
    <axis xyz="1 0 0"/>
    <limit effort="2.8" lower="-2.6179939" upper="2.6179939" velocity="5.6548668"/>
  </joint>
  <transmission name="t_c1_rf">
    <type>transmission_interface/SimpleTransmission</type>
    <joint name="j_c1_rf">
      <hardwareInterface>EffortJointInterface</hardwareInterface>
    </joint>
    <actuator name="m_c1_rf">
      <hardwareInterface>EffortJointInterface</hardwareInterface>
      <mechanicalReduction>1</mechanicalReduction>
    </actuator>
  </transmission>
  <transmission name="t_thigh_rf">
    <type>transmission_interface/SimpleTransmission</type>
    <joint name="j_thigh_rf">
      <hardwareInterface>EffortJointInterface</hardwareInterface>
    </joint>
    <actuator name="m_thigh_rf">
      <hardwareInterface>EffortJointInterface</hardwareInterface>
      <mechanicalReduction>1</mechanicalReduction>
    </actuator>
  </transmission>
  <transmission name="t_tibia_rf">
    <type>transmission_interface/SimpleTransmission</type>
    <joint name="j_tibia_rf">
      <hardwareInterface>EffortJointInterface</hardwareInterface>
    </joint>
    <actuator name="m_tibia_rf">
      <hardwareInterface>EffortJointInterface</hardwareInterface>
      <mechanicalReduction>1</mechanicalReduction>
    </actuator>
  </transmission>
  <link name="c1_rm">
    <inertial>
      <origin rpy="0 0 0" xyz="0 -0.02633 0"/>
      <mass value="0.024357719"/>
      <inertia ixx="0.0051411124" ixy="-0.00057530255" ixz="-0.000024729049" iyy="0.0081915737" iyz="-0.000019223094" izz="0.0011379812"/>
    </inertial>
    <visual>
      <origin rpy="0 0 0" xyz="0 -0.0252 0"/>
      <geometry>
        <!--box size="0.045 0.022 0.0325" /-->
        <mesh filename="meshes/connect.STL" scale="1 1 1"/>
      </geometry>
      <material name="Yellow"/>
    </visual>
    <collision>
      <origin rpy="0 0 0" xyz="0 -0.02633 0"/>
      <geometry>
        <mesh filename="meshes/connect_coll.STL" scale="1 1 1"/>
      </geometry>
    </collision>
  </link>
  <link name="c2_rm">
    <inertial>
      <origin rpy="0 0 0" xyz="0 -0.02633 0"/>
      <mass value="0.024357719"/>
      <inertia ixx="0.0051411124" ixy="-0.00057530255" ixz="-0.000024729049" iyy="0.0081915737" iyz="-0.000019223094" izz="0.0011379812"/>
    </inertial>
    <visual>
      <origin rpy="0 0 0" xyz="0 -0.0252 0"/>
      <geometry>
        <!--box size="0.045 0.022 0.0325" /-->
        <mesh filename="meshes/connect.STL" scale="1 1 1"/>
      </geometry>
      <material name="Yellow"/>
    </visual>
    <collision>
      <origin rpy="0 0 0" xyz="0 -0.02633 0"/>
      <geometry>
        <mesh filename="meshes/connect_coll.STL" scale="1 1 1"/>
      </geometry>
    </collision>
  </link>
  <link name="thigh_rm">
    <inertial>
      <origin rpy="0 0 0" xyz="0 0 0"/>
      <mass value="0.024357719"/>
      <inertia ixx="0.0051411124" ixy="-0.00057530255" ixz="-0.000024729049" iyy="0.0081915737" iyz="-0.000019223094" izz="0.0011379812"/>
    </inertial>
    <visual>
      <origin rpy="0 0 0" xyz="0 0 0"/>
      <geometry>
        <!--box size="0.045 0.022 0.0325" /-->
        <mesh filename="meshes/thigh_l.STL" scale="1 1 1"/>
      </geometry>
      <material name="DarkGreen"/>
    </visual>
    <collision>
      <origin rpy="0 0 0" xyz="0 0 0"/>
      <geometry>
        <mesh filename="meshes/thigh_l_coll.STL" scale="1 1 1"/>
      </geometry>
    </collision>
  </link>
  <link name="tibia_rm">
    <inertial>
      <origin rpy="0 0 0" xyz="0 0 0"/>
      <mass value="0.024357719"/>
      <inertia ixx="0.0051411124" ixy="-0.00057530255" ixz="-0.000024729049" iyy="0.0081915737" iyz="-0.000019223094" izz="0.0011379812"/>
    </inertial>
    <visual>
      <origin rpy="0 0 0" xyz="0 0 0"/>
      <geometry>
        <!--box size="0.045 0.022 0.0325" /-->
        <mesh filename="meshes/tibia_l.STL" scale="1 1 1"/>
      </geometry>
      <material name="Blue"/>
    </visual>
    <collision>
      <origin rpy="0 0 0" xyz="0 0 0"/>
      <geometry>
        <mesh filename="meshes/tibia_l_coll.STL" scale="1 1 1"/>
      </geometry>
    </collision>
  </link>
  <joint name="j_c1_rm" type="revolute">
    <parent link="MP_BODY"/>
    <child link="c1_rm"/>
    <origin rpy="0 4.7123 0" xyz="0 -0.1034  0.001116"/>
    <axis xyz="1 0 0"/>
    <limit effort="2.8" lower="-2.6179939" upper="2.6179939" velocity="5.6548668"/>
  </joint>
  <joint name="j_c2_rm" type="fixed">
    <parent link="c1_rm"/>
    <child link="c2_rm"/>
    <origin rpy="0 1.5704 3.14159" xyz="0 -0.054 0"/>
  </joint>
  <joint name="j_thigh_rm" type="revolute">
    <parent link="c2_rm"/>
    <child link="thigh_rm"/>
    <origin rpy=" 0 3.14159 3.14159" xyz="0 0 0"/>
    <axis xyz="1 0 0"/>
    <limit effort="2.8" lower="-2.6179939" upper="2.6179939" velocity="5.6548668"/>
  </joint>
  <joint name="j_tibia_rm" type="revolute">
    <parent link="thigh_rm"/>
    <child link="tibia_rm"/>
    <origin rpy="-1.5707 0 3.14159" xyz="0 -0.0645 -0.0145"/>
    <axis xyz="1 0 0"/>
    <limit effort="2.8" lower="-2.6179939" upper="2.6179939" velocity="5.6548668"/>
  </joint>
  <transmission name="t_c1_rm">
    <type>transmission_interface/SimpleTransmission</type>
    <joint name="j_c1_rm">
      <hardwareInterface>EffortJointInterface</hardwareInterface>
    </joint>
    <actuator name="m_c1_rm">
      <hardwareInterface>EffortJointInterface</hardwareInterface>
      <mechanicalReduction>1</mechanicalReduction>
    </actuator>
  </transmission>
  <transmission name="t_thigh_rm">
    <type>transmission_interface/SimpleTransmission</type>
    <joint name="j_thigh_rm">
      <hardwareInterface>EffortJointInterface</hardwareInterface>
    </joint>
    <actuator name="m_thigh_rm">
      <hardwareInterface>EffortJointInterface</hardwareInterface>
      <mechanicalReduction>1</mechanicalReduction>
    </actuator>
  </transmission>
  <transmission name="t_tibia_rm">
    <type>transmission_interface/SimpleTransmission</type>
    <joint name="j_tibia_rm">
      <hardwareInterface>EffortJointInterface</hardwareInterface>
    </joint>
    <actuator name="m_tibia_rm">
      <hardwareInterface>EffortJointInterface</hardwareInterface>
      <mechanicalReduction>1</mechanicalReduction>
    </actuator>
  </transmission>
  <link name="c1_rr">
    <inertial>
      <origin rpy="0 0 0" xyz="0 -0.02633 0"/>
      <mass value="0.024357719"/>
      <inertia ixx="0.0051411124" ixy="-0.00057530255" ixz="-0.000024729049" iyy="0.0081915737" iyz="-0.000019223094" izz="0.0011379812"/>
    </inertial>
    <visual>
      <origin rpy="0 0 0" xyz="0 -0.0252 0"/>
      <geometry>
        <!--box size="0.045 0.022 0.0325" /-->
        <mesh filename="meshes/connect.STL" scale="1 1 1"/>
      </geometry>
      <material name="Yellow"/>
    </visual>
    <collision>
      <origin rpy="0 0 0" xyz="0 -0.02633 0"/>
      <geometry>
        <mesh filename="meshes/connect_coll.STL" scale="1 1 1"/>
      </geometry>
    </collision>
  </link>
  <link name="c2_rr">
    <inertial>
      <origin rpy="0 0 0" xyz="0 -0.02633 0"/>
      <mass value="0.024357719"/>
      <inertia ixx="0.0051411124" ixy="-0.00057530255" ixz="-0.000024729049" iyy="0.0081915737" iyz="-0.000019223094" izz="0.0011379812"/>
    </inertial>
    <visual>
      <origin rpy="0 0 0" xyz="0 -0.0252 0"/>
      <geometry>
        <!--box size="0.045 0.022 0.0325" /-->
        <mesh filename="meshes/connect.STL" scale="1 1 1"/>
      </geometry>
      <material name="Yellow"/>
    </visual>
    <collision>
      <origin rpy="0 0 0" xyz="0 -0.02633 0"/>
      <geometry>
        <mesh filename="meshes/connect_coll.STL" scale="1 1 1"/>
      </geometry>
    </collision>
  </link>
  <link name="thigh_rr">
    <inertial>
      <origin rpy="0 0 0" xyz="0 0 0"/>
      <mass value="0.024357719"/>
      <inertia ixx="0.0051411124" ixy="-0.00057530255" ixz="-0.000024729049" iyy="0.0081915737" iyz="-0.000019223094" izz="0.0011379812"/>
    </inertial>
    <visual>
      <origin rpy="0 0 0" xyz="0 0 0"/>
      <geometry>
        <!--box size="0.045 0.022 0.0325" /-->
        <mesh filename="meshes/thigh_l.STL" scale="1 1 1"/>
      </geometry>
      <material name="DarkGreen"/>
    </visual>
    <collision>
      <origin rpy="0 0 0" xyz="0 0 0"/>
      <geometry>
        <mesh filename="meshes/thigh_l_coll.STL" scale="1 1 1"/>
      </geometry>
    </collision>
  </link>
  <link name="tibia_rr">
    <inertial>
      <origin rpy="0 0 0" xyz="0 0 0"/>
      <mass value="0.024357719"/>
      <inertia ixx="0.0051411124" ixy="-0.00057530255" ixz="-0.000024729049" iyy="0.0081915737" iyz="-0.000019223094" izz="0.0011379812"/>
    </inertial>
    <visual>
      <origin rpy="0 0 0" xyz="0 0 0"/>
      <geometry>
        <!--box size="0.045 0.022 0.0325" /-->
        <mesh filename="meshes/tibia_l.STL" scale="1 1 1"/>
      </geometry>
      <material name="Blue"/>
    </visual>
    <collision>
      <origin rpy="0 0 0" xyz="0 0 0"/>
      <geometry>
        <mesh filename="meshes/tibia_l_coll.STL" scale="1 1 1"/>
      </geometry>
    </collision>
  </link>
  <joint name="j_c1_rr" type="revolute">
    <parent link="MP_BODY"/>
    <child link="c1_rr"/>
    <origin rpy="0 4.7123 -0.7853981633974483" xyz="-0.1248 -0.06164  0.001116"/>
    <axis xyz="1 0 0"/>
    <limit effort="2.8" lower="-2.6179939" upper="2.6179939" velocity="5.6548668"/>
  </joint>
  <joint name="j_c2_rr" type="fixed">
    <parent link="c1_rr"/>
    <child link="c2_rr"/>
    <origin rpy="0 1.5704 3.14159" xyz="0 -0.054 0"/>
  </joint>
  <joint name="j_thigh_rr" type="revolute">
    <parent link="c2_rr"/>
    <child link="thigh_rr"/>
    <origin rpy=" 0 3.14159 3.14159" xyz="0 0 0"/>
    <axis xyz="1 0 0"/>
    <limit effort="2.8" lower="-2.6179939" upper="2.6179939" velocity="5.6548668"/>
  </joint>
  <joint name="j_tibia_rr" type="revolute">
    <parent link="thigh_rr"/>
    <child link="tibia_rr"/>
    <origin rpy="-1.5707 0 3.14159" xyz="0 -0.0645 -0.0145"/>
    <axis xyz="1 0 0"/>
    <limit effort="2.8" lower="-2.6179939" upper="2.6179939" velocity="5.6548668"/>
  </joint>
  <transmission name="t_c1_rr">
    <type>transmission_interface/SimpleTransmission</type>
    <joint name="j_c1_rr">
      <hardwareInterface>EffortJointInterface</hardwareInterface>
    </joint>
    <actuator name="m_c1_rr">
      <hardwareInterface>EffortJointInterface</hardwareInterface>
      <mechanicalReduction>1</mechanicalReduction>
    </actuator>
  </transmission>
  <transmission name="t_thigh_rr">
    <type>transmission_interface/SimpleTransmission</type>
    <joint name="j_thigh_rr">
      <hardwareInterface>EffortJointInterface</hardwareInterface>
    </joint>
    <actuator name="m_thigh_rr">
      <hardwareInterface>EffortJointInterface</hardwareInterface>
      <mechanicalReduction>1</mechanicalReduction>
    </actuator>
  </transmission>
  <transmission name="t_tibia_rr">
    <type>transmission_interface/SimpleTransmission</type>
    <joint name="j_tibia_rr">
      <hardwareInterface>EffortJointInterface</hardwareInterface>
    </joint>
    <actuator name="m_tibia_rr">
      <hardwareInterface>EffortJointInterface</hardwareInterface>
      <mechanicalReduction>1</mechanicalReduction>
    </actuator>
  </transmission>
  <link name="c1_lf">
    <inertial>
      <origin rpy="0 0 0" xyz="0 -0.02633 0"/>
      <mass value="0.024357719"/>
      <inertia ixx="0.0051411124" ixy="-0.00057530255" ixz="-0.000024729049" iyy="0.0081915737" iyz="-0.000019223094" izz="0.0011379812"/>
    </inertial>
    <visual>
      <origin rpy="0 0 0" xyz="0 -0.0252 0"/>
      <geometry>
        <!--box size="0.045 0.022 0.0325" /-->
        <mesh filename="meshes/connect.STL" scale="1 1 1"/>
      </geometry>
      <material name="Yellow"/>
    </visual>
    <collision>
      <origin rpy="0 0 0" xyz="0 -0.02633 0"/>
      <geometry>
        <mesh filename="meshes/connect_coll.STL" scale="1 1 1"/>
      </geometry>
    </collision>
  </link>
  <link name="c2_lf">
    <inertial>
      <origin rpy="0 0 0" xyz="0 -0.02633 0"/>
      <mass value="0.024357719"/>
      <inertia ixx="0.0051411124" ixy="-0.00057530255" ixz="-0.000024729049" iyy="0.0081915737" iyz="-0.000019223094" izz="0.0011379812"/>
    </inertial>
    <visual>
      <origin rpy="0 0 0" xyz="0 -0.0252 0"/>
      <geometry>
        <!--box size="0.045 0.022 0.0325" /-->
        <mesh filename="meshes/connect.STL" scale="1 1 1"/>
      </geometry>
      <material name="Yellow"/>
    </visual>
    <collision>
      <origin rpy="0 0 0" xyz="0 -0.02633 0"/>
      <geometry>
        <mesh filename="meshes/connect_coll.STL" scale="1 1 1"/>
      </geometry>
    </collision>
  </link>
  <link name="thigh_lf">
    <inertial>
      <origin rpy="0 0 0" xyz="0 0 0"/>
      <mass value="0.024357719"/>
      <inertia ixx="0.0051411124" ixy="-0.00057530255" ixz="-0.000024729049" iyy="0.0081915737" iyz="-0.000019223094" izz="0.0011379812"/>
    </inertial>
    <visual>
      <origin rpy="0 0 0" xyz="0 0 0"/>
      <geometry>
        <!--box size="0.045 0.022 0.0325" /-->
        <mesh filename="meshes/thigh_l.STL" scale="1 1 1"/>
      </geometry>
      <material name="DarkGreen"/>
    </visual>
    <collision>
      <origin rpy="0 0 0" xyz="0 0 0"/>
      <geometry>
        <mesh filename="meshes/thigh_l_coll.STL" scale="1 1 1"/>
      </geometry>
    </collision>
  </link>
  <link name="tibia_lf">
    <inertial>
      <origin rpy="0 0 0" xyz="0 0 0"/>
      <mass value="0.024357719"/>
      <inertia ixx="0.0051411124" ixy="-0.00057530255" ixz="-0.000024729049" iyy="0.0081915737" iyz="-0.000019223094" izz="0.0011379812"/>
    </inertial>
    <visual>
      <origin rpy="0 0 0" xyz="0 0 0"/>
      <geometry>
        <!--box size="0.045 0.022 0.0325" /-->
        <mesh filename="meshes/tibia_l.STL" scale="1 1 1"/>
      </geometry>
      <material name="Blue"/>
    </visual>
    <collision>
      <origin rpy="0 0 0" xyz="0 0 0"/>
      <geometry>
        <mesh filename="meshes/tibia_l_coll.STL" scale="1 1 1"/>
      </geometry>
    </collision>
  </link>
  <joint name="j_c1_lf" type="revolute">
    <parent link="MP_BODY"/>
    <child link="c1_lf"/>
    <origin rpy="0 4.7123 2.356194490192345" xyz="0.1248 0.06164  0.001116"/>
    <axis xyz="1 0 0"/>
    <limit effort="2.8" lower="-2.6179939" upper="2.6179939" velocity="5.6548668"/>
  </joint>
  <joint name="j_c2_lf" type="fixed">
    <parent link="c1_lf"/>
    <child link="c2_lf"/>
    <origin rpy="0 1.5704 3.14159" xyz="0 -0.054 0"/>
  </joint>
  <joint name="j_thigh_lf" type="revolute">
    <parent link="c2_lf"/>
    <child link="thigh_lf"/>
    <origin rpy=" 0 3.14159 3.14159" xyz="0 0 0"/>
    <axis xyz="1 0 0"/>
    <limit effort="2.8" lower="-2.6179939" upper="2.6179939" velocity="5.6548668"/>
  </joint>
  <joint name="j_tibia_lf" type="revolute">
    <parent link="thigh_lf"/>
    <child link="tibia_lf"/>
    <origin rpy="-1.5707 0 3.14159" xyz="0 -0.0645 -0.0145"/>
    <axis xyz="1 0 0"/>
    <limit effort="2.8" lower="-2.6179939" upper="2.6179939" velocity="5.6548668"/>
  </joint>
  <transmission name="t_c1_lf">
    <type>transmission_interface/SimpleTransmission</type>
    <joint name="j_c1_lf">
      <hardwareInterface>EffortJointInterface</hardwareInterface>
    </joint>
    <actuator name="m_c1_lf">
      <hardwareInterface>EffortJointInterface</hardwareInterface>
      <mechanicalReduction>1</mechanicalReduction>
    </actuator>
  </transmission>
  <transmission name="t_thigh_lf">
    <type>transmission_interface/SimpleTransmission</type>
    <joint name="j_thigh_lf">
      <hardwareInterface>EffortJointInterface</hardwareInterface>
    </joint>
    <actuator name="m_thigh_lf">
      <hardwareInterface>EffortJointInterface</hardwareInterface>
      <mechanicalReduction>1</mechanicalReduction>
    </actuator>
  </transmission>
  <transmission name="t_tibia_lf">
    <type>transmission_interface/SimpleTransmission</type>
    <joint name="j_tibia_lf">
      <hardwareInterface>EffortJointInterface</hardwareInterface>
    </joint>
    <actuator name="m_tibia_lf">
      <hardwareInterface>EffortJointInterface</hardwareInterface>
      <mechanicalReduction>1</mechanicalReduction>
    </actuator>
  </transmission>
  <link name="c1_lm">
    <inertial>
      <origin rpy="0 0 0" xyz="0 -0.02633 0"/>
      <mass value="0.024357719"/>
      <inertia ixx="0.0051411124" ixy="-0.00057530255" ixz="-0.000024729049" iyy="0.0081915737" iyz="-0.000019223094" izz="0.0011379812"/>
    </inertial>
    <visual>
      <origin rpy="0 0 0" xyz="0 -0.0252 0"/>
      <geometry>
        <!--box size="0.045 0.022 0.0325" /-->
        <mesh filename="meshes/connect.STL" scale="1 1 1"/>
      </geometry>
      <material name="Yellow"/>
    </visual>
    <collision>
      <origin rpy="0 0 0" xyz="0 -0.02633 0"/>
      <geometry>
        <mesh filename="meshes/connect_coll.STL" scale="1 1 1"/>
      </geometry>
    </collision>
  </link>
  <link name="c2_lm">
    <inertial>
      <origin rpy="0 0 0" xyz="0 -0.02633 0"/>
      <mass value="0.024357719"/>
      <inertia ixx="0.0051411124" ixy="-0.00057530255" ixz="-0.000024729049" iyy="0.0081915737" iyz="-0.000019223094" izz="0.0011379812"/>
    </inertial>
    <visual>
      <origin rpy="0 0 0" xyz="0 -0.0252 0"/>
      <geometry>
        <!--box size="0.045 0.022 0.0325" /-->
        <mesh filename="meshes/connect.STL" scale="1 1 1"/>
      </geometry>
      <material name="Yellow"/>
    </visual>
    <collision>
      <origin rpy="0 0 0" xyz="0 -0.02633 0"/>
      <geometry>
        <mesh filename="meshes/connect_coll.STL" scale="1 1 1"/>
      </geometry>
    </collision>
  </link>
  <link name="thigh_lm">
    <inertial>
      <origin rpy="0 0 0" xyz="0 0 0"/>
      <mass value="0.024357719"/>
      <inertia ixx="0.0051411124" ixy="-0.00057530255" ixz="-0.000024729049" iyy="0.0081915737" iyz="-0.000019223094" izz="0.0011379812"/>
    </inertial>
    <visual>
      <origin rpy="0 0 0" xyz="0 0 0"/>
      <geometry>
        <!--box size="0.045 0.022 0.0325" /-->
        <mesh filename="meshes/thigh_l.STL" scale="1 1 1"/>
      </geometry>
      <material name="DarkGreen"/>
    </visual>
    <collision>
      <origin rpy="0 0 0" xyz="0 0 0"/>
      <geometry>
        <mesh filename="meshes/thigh_l_coll.STL" scale="1 1 1"/>
      </geometry>
    </collision>
  </link>
  <link name="tibia_lm">
    <inertial>
      <origin rpy="0 0 0" xyz="0 0 0"/>
      <mass value="0.024357719"/>
      <inertia ixx="0.0051411124" ixy="-0.00057530255" ixz="-0.000024729049" iyy="0.0081915737" iyz="-0.000019223094" izz="0.0011379812"/>
    </inertial>
    <visual>
      <origin rpy="0 0 0" xyz="0 0 0"/>
      <geometry>
        <!--box size="0.045 0.022 0.0325" /-->
        <mesh filename="meshes/tibia_l.STL" scale="1 1 1"/>
      </geometry>
      <material name="Blue"/>
    </visual>
    <collision>
      <origin rpy="0 0 0" xyz="0 0 0"/>
      <geometry>
        <mesh filename="meshes/tibia_l_coll.STL" scale="1 1 1"/>
      </geometry>
    </collision>
  </link>
  <joint name="j_c1_lm" type="revolute">
    <parent link="MP_BODY"/>
    <child link="c1_lm"/>
    <origin rpy="0 4.7123 3.14159" xyz="0 0.1034  0.001116"/>
    <axis xyz="1 0 0"/>
    <limit effort="2.8" lower="-2.6179939" upper="2.6179939" velocity="5.6548668"/>
  </joint>
  <joint name="j_c2_lm" type="fixed">
    <parent link="c1_lm"/>
    <child link="c2_lm"/>
    <origin rpy="0 1.5704 3.14159" xyz="0 -0.054 0"/>
  </joint>
  <joint name="j_thigh_lm" type="revolute">
    <parent link="c2_lm"/>
    <child link="thigh_lm"/>
    <origin rpy=" 0 3.14159 3.14159" xyz="0 0 0"/>
    <axis xyz="1 0 0"/>
    <limit effort="2.8" lower="-2.6179939" upper="2.6179939" velocity="5.6548668"/>
  </joint>
  <joint name="j_tibia_lm" type="revolute">
    <parent link="thigh_lm"/>
    <child link="tibia_lm"/>
    <origin rpy="-1.5707 0 3.14159" xyz="0 -0.0645 -0.0145"/>
    <axis xyz="1 0 0"/>
    <limit effort="2.8" lower="-2.6179939" upper="2.6179939" velocity="5.6548668"/>
  </joint>
  <transmission name="t_c1_lm">
    <type>transmission_interface/SimpleTransmission</type>
    <joint name="j_c1_lm">
      <hardwareInterface>EffortJointInterface</hardwareInterface>
    </joint>
    <actuator name="m_c1_lm">
      <hardwareInterface>EffortJointInterface</hardwareInterface>
      <mechanicalReduction>1</mechanicalReduction>
    </actuator>
  </transmission>
  <transmission name="t_thigh_lm">
    <type>transmission_interface/SimpleTransmission</type>
    <joint name="j_thigh_lm">
      <hardwareInterface>EffortJointInterface</hardwareInterface>
    </joint>
    <actuator name="m_thigh_lm">
      <hardwareInterface>EffortJointInterface</hardwareInterface>
      <mechanicalReduction>1</mechanicalReduction>
    </actuator>
  </transmission>
  <transmission name="t_tibia_lm">
    <type>transmission_interface/SimpleTransmission</type>
    <joint name="j_tibia_lm">
      <hardwareInterface>EffortJointInterface</hardwareInterface>
    </joint>
    <actuator name="m_tibia_lm">
      <hardwareInterface>EffortJointInterface</hardwareInterface>
      <mechanicalReduction>1</mechanicalReduction>
    </actuator>
  </transmission>
  <link name="c1_lr">
    <inertial>
      <origin rpy="0 0 0" xyz="0 -0.02633 0"/>
      <mass value="0.024357719"/>
      <inertia ixx="0.0051411124" ixy="-0.00057530255" ixz="-0.000024729049" iyy="0.0081915737" iyz="-0.000019223094" izz="0.0011379812"/>
    </inertial>
    <visual>
      <origin rpy="0 0 0" xyz="0 -0.0252 0"/>
      <geometry>
        <!--box size="0.045 0.022 0.0325" /-->
        <mesh filename="meshes/connect.STL" scale="1 1 1"/>
      </geometry>
      <material name="Yellow"/>
    </visual>
    <collision>
      <origin rpy="0 0 0" xyz="0 -0.02633 0"/>
      <geometry>
        <mesh filename="meshes/connect_coll.STL" scale="1 1 1"/>
      </geometry>
    </collision>
  </link>
  <link name="c2_lr">
    <inertial>
      <origin rpy="0 0 0" xyz="0 -0.02633 0"/>
      <mass value="0.024357719"/>
      <inertia ixx="0.0051411124" ixy="-0.00057530255" ixz="-0.000024729049" iyy="0.0081915737" iyz="-0.000019223094" izz="0.0011379812"/>
    </inertial>
    <visual>
      <origin rpy="0 0 0" xyz="0 -0.0252 0"/>
      <geometry>
        <!--box size="0.045 0.022 0.0325" /-->
        <mesh filename="meshes/connect.STL" scale="1 1 1"/>
      </geometry>
      <material name="Yellow"/>
    </visual>
    <collision>
      <origin rpy="0 0 0" xyz="0 -0.02633 0"/>
      <geometry>
        <mesh filename="meshes/connect_coll.STL" scale="1 1 1"/>
      </geometry>
    </collision>
  </link>
  <link name="thigh_lr">
    <inertial>
      <origin rpy="0 0 0" xyz="0 0 0"/>
      <mass value="0.024357719"/>
      <inertia ixx="0.0051411124" ixy="-0.00057530255" ixz="-0.000024729049" iyy="0.0081915737" iyz="-0.000019223094" izz="0.0011379812"/>
    </inertial>
    <visual>
      <origin rpy="0 0 0" xyz="0 0 0"/>
      <geometry>
        <!--box size="0.045 0.022 0.0325" /-->
        <mesh filename="meshes/thigh_l.STL" scale="1 1 1"/>
      </geometry>
      <material name="DarkGreen"/>
    </visual>
    <collision>
      <origin rpy="0 0 0" xyz="0 0 0"/>
      <geometry>
        <mesh filename="meshes/thigh_l_coll.STL" scale="1 1 1"/>
      </geometry>
    </collision>
  </link>
  <link name="tibia_lr">
    <inertial>
      <origin rpy="0 0 0" xyz="0 0 0"/>
      <mass value="0.024357719"/>
      <inertia ixx="0.0051411124" ixy="-0.00057530255" ixz="-0.000024729049" iyy="0.0081915737" iyz="-0.000019223094" izz="0.0011379812"/>
    </inertial>
    <visual>
      <origin rpy="0 0 0" xyz="0 0 0"/>
      <geometry>
        <!--box size="0.045 0.022 0.0325" /-->
        <mesh filename="meshes/tibia_l.STL" scale="1 1 1"/>
      </geometry>
      <material name="Blue"/>
    </visual>
    <collision>
      <origin rpy="0 0 0" xyz="0 0 0"/>
      <geometry>
        <mesh filename="meshes/tibia_l_coll.STL" scale="1 1 1"/>
      </geometry>
    </collision>
  </link>
  <joint name="j_c1_lr" type="revolute">
    <parent link="MP_BODY"/>
    <child link="c1_lr"/>
    <origin rpy="0 4.7123 3.9269908169872414" xyz="-0.1248 0.06164  0.001116"/>
    <axis xyz="1 0 0"/>
    <limit effort="2.8" lower="-2.6179939" upper="2.6179939" velocity="5.6548668"/>
  </joint>
  <joint name="j_c2_lr" type="fixed">
    <parent link="c1_lr"/>
    <child link="c2_lr"/>
    <origin rpy="0 1.5704 3.14159" xyz="0 -0.054 0"/>
  </joint>
  <joint name="j_thigh_lr" type="revolute">
    <parent link="c2_lr"/>
    <child link="thigh_lr"/>
    <origin rpy=" 0 3.14159 3.14159" xyz="0 0 0"/>
    <axis xyz="1 0 0"/>
    <limit effort="2.8" lower="-2.6179939" upper="2.6179939" velocity="5.6548668"/>
  </joint>
  <joint name="j_tibia_lr" type="revolute">
    <parent link="thigh_lr"/>
    <child link="tibia_lr"/>
    <origin rpy="-1.5707 0 3.14159" xyz="0 -0.0645 -0.0145"/>
    <axis xyz="1 0 0"/>
    <limit effort="2.8" lower="-2.6179939" upper="2.6179939" velocity="5.6548668"/>
  </joint>
  <transmission name="t_c1_lr">
    <type>transmission_interface/SimpleTransmission</type>
    <joint name="j_c1_lr">
      <hardwareInterface>EffortJointInterface</hardwareInterface>
    </joint>
    <actuator name="m_c1_lr">
      <hardwareInterface>EffortJointInterface</hardwareInterface>
      <mechanicalReduction>1</mechanicalReduction>
    </actuator>
  </transmission>
  <transmission name="t_thigh_lr">
    <type>transmission_interface/SimpleTransmission</type>
    <joint name="j_thigh_lr">
      <hardwareInterface>EffortJointInterface</hardwareInterface>
    </joint>
    <actuator name="m_thigh_lr">
      <hardwareInterface>EffortJointInterface</hardwareInterface>
      <mechanicalReduction>1</mechanicalReduction>
    </actuator>
  </transmission>
  <transmission name="t_tibia_lr">
    <type>transmission_interface/SimpleTransmission</type>
    <joint name="j_tibia_lr">
      <hardwareInterface>EffortJointInterface</hardwareInterface>
    </joint>
    <actuator name="m_tibia_lr">
      <hardwareInterface>EffortJointInterface</hardwareInterface>
      <mechanicalReduction>1</mechanicalReduction>
    </actuator>
  </transmission>
</robot>

