<?xml version="1.0" ?>
<robot xmlns:xacro="http://www.ros.org/wiki/xacro" name="phantomx">

<xacro:property name="connect_offset" value="0.02633" />
<xacro:property name="thigh_offset_y" value="-0.0645" />
<xacro:property name="thigh_offset_z" value="-0.0145" />
<xacro:property name="phantomx_body_color" value="Red" />
<xacro:property name="phantomx_connect_color" value="Yellow" />
<xacro:property name="phantomx_thigh_color" value="DarkGreen" />
<xacro:property name="phantomx_tibia_color" value="Blue" />

 <material name="Blue">
    <color rgba="0.33 0.25 1.0 1.0"/>
  </material>
  <material name="DarkBlue">
    <color rgba="0.03 0.16 0.8 1.0"/>
  </material>
  <material name="Green">
    <color rgba="0.0 0.8 0.0 1.0"/>
  </material>
  <material name="Grey">
    <color rgba="0.7 0.7 0.7 1.0"/>
  </material>
  <material name="DarkGreen">
    <color rgba="0.4 0.6 0.24 1.0"/>
  </material>
  <material name="Red">
    <color rgba="0.48 0.03 0.03 1.0"/>
  </material>
  <material name="White">
    <color rgba="1.0 1.0 1.0 1.0"/>
  </material>
  <material name="Yellow">
    <color rgba="1.0 0.8 0.0 1.0"/>
  </material>

<!-- Build the body frame -->
	<link name="base_link" />

      <joint name="j_phantomx_attachment" type="fixed">
         <parent link="base_link" />
        <child link="MP_BODY"/>
		<origin xyz="0 0 0" rpy="0 0 0" />
      </joint>
      

      <link name="MP_BODY">
        <inertial>
          <origin xyz="0 0 0" />
          <mass value="0.97559947"/>
          <inertia ixx="3.1081800"  ixy="-0.25460189"  ixz="2.0318174" iyy="6.3787776" iyz="0.16417863" izz="5.3316425" />
        </inertial>
        <visual>
          <!--origin xyz="-0.0235 0 -0.03525" rpy="0 0 0" /-->
          <origin xyz="0 0 0" rpy="0 0 0" />
          <geometry>
            <!--box size="0.102 0.109 0.106" /-->
            <mesh filename="meshes/body.STL"  scale="1 1 1"/>
          </geometry>
          <material name="${phantomx_body_color}" />


        </visual>
        <collision>
          <origin xyz="0 0 0" rpy="0 0 0" />
          <geometry>
            <mesh filename="meshes/body_coll.STL"  scale="1 1 1"/>
          </geometry>

        </collision>
      </link>

    <xacro:leg_l xyz="0.1248 -0.06164  0.001116"  rpy="0 4.7123 0.7853981633974483" suffix="rf"/>
    <xacro:leg_l xyz="0 -0.1034  0.001116"  rpy="0 4.7123 0" suffix="rm"/>
    <xacro:leg_l xyz="-0.1248 -0.06164  0.001116"  rpy="0 4.7123 -0.7853981633974483" suffix="rr"/>


    <xacro:leg_l xyz="0.1248 0.06164  0.001116"  rpy="0 4.7123 2.356194490192345" suffix="lf"/>
    <xacro:leg_l xyz="0 0.1034  0.001116"  rpy="0 4.7123 3.14159" suffix="lm"/>
    <xacro:leg_l xyz="-0.1248 0.06164  0.001116"  rpy="0 4.7123 3.9269908169872414" suffix="lr"/>


 <xacro:macro name="leg_l" params="xyz rpy suffix">



  <link name="c1_${suffix}">
    <inertial>
      <origin xyz="0 -${connect_offset} 0" rpy="0 0 0"  />
      <mass value="0.024357719"/>
     <inertia ixx="0.0051411124"  ixy="-0.00057530255"  ixz="-0.000024729049" iyy="0.0081915737" iyz="-0.000019223094" izz="0.0011379812" />
    </inertial>
    <visual>
      <origin xyz="0 -0.0252 0" rpy="0 0 0"  />
      <geometry>
        <!--box size="0.045 0.022 0.0325" /-->
        <mesh filename="meshes/connect.STL"  scale="1 1 1"/>
      </geometry>
      <material name="${phantomx_connect_color}" />


    </visual>
    <collision>
      <origin xyz="0 -${connect_offset} 0" rpy="0 0 0"  />
      <geometry>
        <mesh filename="meshes/connect_coll.STL"  scale="1 1 1"/>
      </geometry>
    </collision>
  </link>


  <link name="c2_${suffix}">
    <inertial>
      <origin xyz="0 -${connect_offset} 0" rpy="0 0 0"  />
      <mass value="0.024357719"/>
     <inertia ixx="0.0051411124"  ixy="-0.00057530255"  ixz="-0.000024729049" iyy="0.0081915737" iyz="-0.000019223094" izz="0.0011379812" />
    </inertial>
    <visual>
      <origin xyz="0 -0.0252 0" rpy="0 0 0"  />
      <geometry>
        <!--box size="0.045 0.022 0.0325" /-->
        <mesh filename="meshes/connect.STL"  scale="1 1 1"/>
      </geometry>
      <material name="${phantomx_connect_color}" />


    </visual>
    <collision>
      <origin xyz="0 -${connect_offset} 0" rpy="0 0 0"  />
      <geometry>
        <mesh filename="meshes/connect_coll.STL"  scale="1 1 1"/>
      </geometry>
    </collision>
  </link>



  <link name="thigh_${suffix}">
    <inertial>
      <origin xyz="0 0 0" rpy="0 0 0"  />
      <mass value="0.024357719"/>
     <inertia ixx="0.0051411124"  ixy="-0.00057530255"  ixz="-0.000024729049" iyy="0.0081915737" iyz="-0.000019223094" izz="0.0011379812" />
    </inertial>
    <visual>
      <origin xyz="0 0 0" rpy="0 0 0"  />
      <geometry>
        <!--box size="0.045 0.022 0.0325" /-->
        <mesh filename="meshes/thigh_l.STL"  scale="1 1 1"/>
      </geometry>
      <material name="${phantomx_thigh_color}" />


    </visual>
    <collision>
      <origin xyz="0 0 0" rpy="0 0 0"  />
      <geometry>
        <mesh filename="meshes/thigh_l_coll.STL"  scale="1 1 1"/>
      </geometry>
    </collision>
  </link>



  <link name="tibia_${suffix}">
    <inertial>
      <origin xyz="0 0 0" rpy="0 0 0"  />
      <mass value="0.024357719"/>
     <inertia ixx="0.0051411124"  ixy="-0.00057530255"  ixz="-0.000024729049" iyy="0.0081915737" iyz="-0.000019223094" izz="0.0011379812" />
    </inertial>
    <visual>
      <origin xyz="0 0 0" rpy="0 0 0"  />
      <geometry>
        <!--box size="0.045 0.022 0.0325" /-->
        <mesh filename="meshes/tibia_l.STL"  scale="1 1 1"/>
      </geometry>
      <material name="${phantomx_tibia_color}" />


    </visual>
    <collision>
      <origin xyz="0 0 0" rpy="0 0 0"  />
      <geometry>
        <mesh filename="meshes/tibia_l_coll.STL"  scale="1 1 1"/>
      </geometry>
    </collision>
  </link>



  <joint name="j_c1_${suffix}" type="revolute">
    <parent link="MP_BODY"/>
    <child link="c1_${suffix}"/>
    <origin xyz="${xyz}" rpy="${rpy}" />
    <axis xyz="1 0 0" />
    <limit effort="2.8" velocity="5.6548668" lower="-2.6179939" upper="2.6179939" />
  </joint>

  <joint name="j_c2_${suffix}" type="fixed">
    <parent link="c1_${suffix}"/>
    <child link="c2_${suffix}"/>
    <origin xyz="0 -0.054 0" rpy="0 1.5704 3.14159" />
  </joint>


  <joint name="j_thigh_${suffix}" type="revolute">
    <parent link="c2_${suffix}"/>
    <child link="thigh_${suffix}"/>
    <origin xyz="0 0 0" rpy=" 0 3.14159 3.14159" />
    <axis xyz="1 0 0" />
    <limit effort="2.8" velocity="5.6548668" lower="-2.6179939" upper="2.6179939" />
  </joint>

  <joint name="j_tibia_${suffix}" type="revolute">
    <parent link="thigh_${suffix}"/>
    <child link="tibia_${suffix}"/>
    <origin xyz="0 ${thigh_offset_y} ${thigh_offset_z}" rpy="-1.5707 0 3.14159" />
    <axis xyz="1 0 0" />
    <limit effort="2.8" velocity="5.6548668" lower="-2.6179939" upper="2.6179939" />
  </joint>



   <transmission name="t_c1_${suffix}">
    <type>transmission_interface/SimpleTransmission</type>
    <joint name="j_c1_${suffix}">
      <hardwareInterface>EffortJointInterface</hardwareInterface>    
    </joint>
    <actuator name="m_c1_${suffix}">
      <hardwareInterface>EffortJointInterface</hardwareInterface>
      <mechanicalReduction>1</mechanicalReduction>
    </actuator>
  </transmission>


   <transmission name="t_thigh_${suffix}">
    <type>transmission_interface/SimpleTransmission</type>
    <joint name="j_thigh_${suffix}">
      <hardwareInterface>EffortJointInterface</hardwareInterface>    
    </joint>
    <actuator name="m_thigh_${suffix}">
      <hardwareInterface>EffortJointInterface</hardwareInterface>
      <mechanicalReduction>1</mechanicalReduction>
    </actuator>
  </transmission>


   <transmission name="t_tibia_${suffix}">
    <type>transmission_interface/SimpleTransmission</type>
    <joint name="j_tibia_${suffix}">
      <hardwareInterface>EffortJointInterface</hardwareInterface>
    </joint>
    <actuator name="m_tibia_${suffix}">
      <hardwareInterface>EffortJointInterface</hardwareInterface>
      <mechanicalReduction>1</mechanicalReduction>
    </actuator>
  </transmission>
  
</xacro:macro>





</robot>
